<?xml version="1.0" ?>

<robot xmlns:xacro="http://www.ros.org/wiki/xacro">
    <link name="base_link"></link>

    <!-- SLAM specific -->

    <joint name="base_footprint_joint" type="fixed">
        <parent link="base_link" />
        <child link="base_footprint" />
        <origin xyz="0.0 0.0 0.0" rpy="0.0 0.0 0.0" />
    </joint>

    <link name="base_footprint"></link>

    <!-- SLAM specific END -->

    <joint name="chassis_joint" type="fixed">
        <parent link="base_link" />
        <child link="chassis" />
        <origin xyz="-0.0565 0.0 0.0555" />
    </joint>

    <link name="chassis">
        <visual>
            <origin xyz="0.0 0.0 0.0" />
            <geometry>
                <box size="0.253 0.15 0.111" />
            </geometry>
            <material name="giga_grey" />
        </visual>
        <collision>
            <origin xyz="0.0 0.0 0.0" />
            <geometry>
                <box size="0.253 0.15 0.111" />
            </geometry>
        </collision>
        <xacro:inertial_box mass="0.5" x="0.253" y="0.15" z="0.111">
            <origin xyz="0.0 0 0.0" rpy="0.0 0.0 0.0"/>
        </xacro:inertial_box>
    </link>

    <joint name="right_wheel_joint" type="continuous">
        <parent link="base_link" />
        <child link="right_wheel" />
        <origin xyz="0.0 -0.0615 0.0" rpy="1.5707963267948966 0.0 0.0" />
        <axis xyz="0.0 0.0 -1.0" />
    </joint>

    <link name="right_wheel">
        <visual>
            <geometry>
                <cylinder radius="0.034" length="0.025"/>
            </geometry>
            <material name="sky_blue" />
        </visual>
        <collision>
            <geometry>
                <cylinder radius="0.034" length="0.025"/>
            </geometry>
        </collision>
        <xacro:inertial_cylinder mass="0.1" radius="0.034" length="0.025">
            <origin xyz="0.0 0.0 0.0" rpy="0.0 0.0 0.0"/>
        </xacro:inertial_cylinder>
    </link>

    <joint name="left_wheel_joint" type="continuous">
        <parent link="base_link" />
        <child link="left_wheel" />
        <origin xyz="0.0 0.0615 0.0" rpy="4.7123889803846899 0.0 0.0" />
        <axis xyz="0.0 0.0 1.0" />
    </joint>

    <link name="left_wheel">
        <visual>
            <geometry>
                <cylinder radius="0.034" length="0.025"/>
            </geometry>
            <material name="sky_blue" />
        </visual>
        <collision>
            <geometry>
                <cylinder radius="0.034" length="0.025"/>
            </geometry>
        </collision>
        <xacro:inertial_cylinder mass="0.1" radius="0.034" length="0.025">
            <origin xyz="0.0 0.0 0.0" rpy="0.0 0.0 0.0"/>
        </xacro:inertial_cylinder>
    </link>

    <joint name="caster_wheel_joint" type="fixed">
        <parent link="base_link" />
        <child link="caster_wheel" />
        <origin xyz="-0.114 0.0 0.0" />
    </joint>

    <link name="caster_wheel">
        <visual>
            <geometry>
                <sphere radius="0.034" />
            </geometry>
            <material name="sky_blue" />
        </visual>
        <collision>
            <geometry>
                <sphere radius="0.034" />
            </geometry>
        </collision>
        <xacro:inertial_sphere mass="0.1" radius="0.034">
            <origin xyz="0.0 0.0 0.0" rpy="0.0 0.0 0.0"/>
        </xacro:inertial_sphere>
    </link>

</robot>
